python compilation failed!

###output:


###error:
Traceback (most recent call last):
  File "/Users/zhaozhaozhaozhao/Unambigious_prompt/exp/output_tb_gen_tb_20250408/147/pychecker_4.py", line 100, in <module>
    outputs.append( check_output(stimulus_list_scenario))
                    ^^^^^^^^^^^^^^^^^^^^^^^^^^^^^^^^^^^^
  File "/Users/zhaozhaozhaozhao/Unambigious_prompt/exp/output_tb_gen_tb_20250408/147/pychecker_4.py", line 73, in check_output
    input_vars = {k:v[i] for k,v in input_vars_list.items()}
                 ^^^^^^^^^^^^^^^^^^^^^^^^^^^^^^^^^^^^^^^^^^^
  File "/Users/zhaozhaozhaozhao/Unambigious_prompt/exp/output_tb_gen_tb_20250408/147/pychecker_4.py", line 73, in <dictcomp>
    input_vars = {k:v[i] for k,v in input_vars_list.items()}
                    ~^^^
IndexError: list index out of range


